Workbook
Name Attic: 'Cost References'!$C$168:$C$170
Name Microwave: 'Cost References'!$C$202:$C$204
Name WindowsDoors: 'Cost References'!$C$173:$C$174
Name TrueFalse: 'Cost References'!$D$160:$D$161
Name WinterMix: 'Cost References'!$C$69:$C$70
Name RealEstateComm: 'Cost References'!$D$241:$D$244
Name MiniSplit: 'Cost References'!$C$195:$C$199
Name Permits: 'Cost References'!$C$15:$C$17
Name StudWallHeight: 'Cost References'!$D$93:$D$95
Name Electrical: 'Cost References'!$C$144:$C$145
Name Cleaning: 'Cost References'!$D$185:$D$189
Name Insulation: 'Cost References'!$C$165:$C$168
Name FixedPrices: 'Cost References'!$D$225:$D$230
Name ShowerType: 'Cost References'!$C$233:$C$239
Name Cabinets: 'Cost References'!$D$108:$D$121
Name ConcreteWalls: 'Cost References'!$B$74:$B$76
Name Profit: 'Cost References'!$D$207:$D$222
Name CUBICMETERSLAB: LAMBDA(('Take Off'!$D$53*0.09290304*0.1016))
Name CUBICMETERFOUNDATION: LAMBDA(('Take Off'!$C$56/3.28*0.203*'Take Off'!$D$56/3.28))
Name CUBICMETERFOOTING: LAMBDA(('Take Off'!$C$53/3.28*0.5*0.25))
Name DRYWALL_SQFT: LAMBDA(CEILING_SQFT()+WALL_SQFT())
Name WALL_SQFT: LAMBDA('Cost References'!$D$6*('Cost References'!$D$4+1)*8)
Name LINEAR_FOOTAGE: LAMBDA(('Cost References'!$D$2*2)+('Cost References'!$D$3*2))
Name CEILING_SQFT: LAMBDA(('Cost References'!$D$2*'Cost References'!$D$3)*('Cost References'!$D$4+1))

Sheet Take Off
A1: Kestrel Developments - Estimate Form
A2: Client | C2: ----
A3: Date: | C3: =TODAY() -> 46132
A4: Location: | C4: XXX
A5: Agent:
A6: Service | F6: Subtotal | G6: HST | H6: Item total | I6: Running Total
A7: Soft Costs
A8: Overhead | B8: Lot Price
F9: Amount
F10: 135000 | G10: =(F10+D10)*'Cost References'!D11 -> 20250 | H10: =SUM(F10:G10) -> 155250 | I10: =H10 -> 155250 | K10: Material Cost | L10: =H46+H56 -> 11546.342
K11: Labour Costs | L11: =H15+H17+H19+H22+H28+H59+H62+H65+H68+H82+H86+H89+H92+H95+D98+E100+H103+H106+H109+H112+H115+H118+H121+H123+H126+H129+H147+H156+H150+H169 -> 139208.2
K12: Financing per house | L12: =L11+L10 -> 150754.54
K13: Carried by subs | L13: =H89+H82+H103+H56+H46 -> 44206.342
B14: Engineering | K14: Total Financing (with carried items) | L14: =L12-L13 -> 106548.2
F15: 1500 | H15: =SUM(F15:G15) -> 1500 | I15: =H15+I13 -> 1500
B16: Surveys
F17: 850 | H17: =SUM(F17:G17) -> 850 | I17: =H17+I15 -> 2350
B18: Legal
F19: 2500 | H19: =SUM(F19:G19) -> 2500 | I19: =H19+I17 -> 4850
B20: Permits
E21: Choose City
E22: St. John's | F22: =IF(E22='Cost References'!C15,'Cost References'!D15,IF(E22='Cost References'!C16,'Cost References'!D16,IF(E22='Cost References'!C17, 'Cost References'!D17,0))) -> 3000 | H22: =SUM(F22:G22) -> 3000 | I22: =H22+I19 -> 7850
B27: Blueprints
F28: 500 | H28: =SUM(F28:G28) -> 500 | I28: =I26+H28 -> 500
A29: Construction Costs
A30: Lot Prep | B30: Excavation
E31: Included in Lot Price | F31: Amount
G32: =F32*'Cost References'!D11 -> 0 | H32: =F32 | I32: =I28+H32 -> 500
B33: Well
F34: Choose
G35: =F35*'Cost References'!D11 -> 0 | H35: =SUM(F35:G35) -> 0 | I35: =H35+I32 -> 500
B36: Septic
F37: Amount
G38: =F38*'Cost References'!D11 -> 0 | H38: =SUM(F38:G38) -> 0 | I38: =I35+H38 -> 500
B39: Rock Busting
F40: Amount
G41: =F41*'Cost References'!D11 -> 0 | H41: =SUM(F41:G41) -> 0 | I41: =I38+H41 -> 500
B42: Fill
F43: Amount
G44: =F44*'Cost References'!D11 -> 0 | H44: =SUM(F44:G44) -> 0 | I44: =I41+H44 -> 500
...

Sheet Cost References
A1: House Measurement Multipliers
C2: width(ft) | D2: 25 | E2: Fill in quantities
C3: length(ft) | D3: 36
C4: storeys | D4: 2
C5: VB ceiling sqft | D5: =D2*D3 -> 900
C6: linear footage | D6: =LINEAR_FOOTAGE() -> 122
C7: wall sqft | D7: =WALL_SQFT() -> 2928 | E7: *change this formula to read wall height if different that 8'walls
C8: drywall sqft | D8: =DRYWALL_SQFT() -> 5628
A9: Tax
C11: Rate | D11: 0.15
A13: Permits
B15: $9 per $1000 up to $100,000 & $7.20 per $1000 above $100,000 | C15: St. John's | D15: 3000
C16: Paradise | D16: 3000
C17: Mount Pearl | D17: 2000
A19: Financing Interest Charges
D21: 3500
D22: 4000
D23: 4500
D24: 5000
D25: 5500
D26: 6000
D27: 6500
D28: 7000
D29: 7500
D30: 8000
D31: 8500
D32: 9000
... D34: 10000
A37: Well
C39: Drilling per ft | D39: 27
C40: Casing per ft | D40: 45
C41: Drive shoe | D41: 100
C42: Well cap | D42: 55
C44: Well Depths(ft)
C45: 300 | D45: =(C45*D39)+(C45*D40)+D41+D42 -> 21755
C46: 400 | D46: 12845
C47: 500 | D47: 15545
B49: Based on 50' from dwelling | C49: Pump Systems
C50: 300' | D50: 5200
C51: 500' | D51: 6200
...
